<?xml version="1.0"?>

<robot xmlns:xacro="https://www.ros.org/wiki/xacro" name="we_r2_arm">

  <xacro:property name="PI" value="3.14159" />
  <xacro:property name="effort" value="100.0" />
  <xacro:property name="velocity" value="0.5" />

  <xacro:macro name="set_inertial_properties" params="mass ixx iyy izz ixy ixz iyz">
      <inertial>
          <mass value="${mass}" />
          <inertia ixx="${ixx}" ixy="${ixy}" ixz="${ixz}" iyy="${iyy}" iyz="${iyz}" izz="${izz}" />
      </inertial>
  </xacro:macro>

  <link name="world" />

  <link name="base_link">
      <xacro:set_inertial_properties mass="5.4" ixx="0.02" iyy="0.02" izz="0.02" ixy="0.0" ixz="0.0" iyz="0.0" />
      <visual>
          <origin rpy="0 0 0"  xyz="0 0 0" />
          <geometry>
            <mesh filename="package://we_r2_arm_description/meshes/_basement.stl" scale="1 1 1" />
          </geometry>
      </visual>
      <collision>
          <origin rpy="0 0 0"  xyz="0 0 0" />
          <geometry>
            <mesh filename="package://we_r2_arm_description/meshes/_basement.stl" scale="1 1 1" />
          </geometry>
      </collision>
  </link>

  <link name="shoulder_1">
      <xacro:set_inertial_properties mass="5.4" ixx="0.02" iyy="0.02" izz="0.02" ixy="0.0" ixz="0.0" iyz="0.0" />
      <visual>
          <origin rpy="0 0 0"  xyz="0 0 -0.09" />
          <geometry>
            <mesh filename="package://we_r2_arm_description/meshes/_shoulder_link_1.stl" scale="1 1 1" />
          </geometry>
      </visual>
      <collision>
          <origin rpy="0 0 0"  xyz="0 0 -0.09" />
          <geometry>
            <mesh filename="package://we_r2_arm_description/meshes/_shoulder_link_1.stl" scale="1 1 1" />
          </geometry>
      </collision>
  </link>

  <link name="shoulder_2">
      <xacro:set_inertial_properties mass="5.4" ixx="0.02" iyy="0.02" izz="0.02" ixy="0.0" ixz="0.0" iyz="0.0" />
      <visual>
          <origin rpy="0 0 0"  xyz="-0.0975 0 -0.1225" />
          <geometry>
            <mesh filename="package://we_r2_arm_description/meshes/_shoulder_link_2.stl" scale="1 1 1" />
          </geometry>
      </visual>
      <collision>
          <origin rpy="0 0 0"  xyz="-0.0975 0 -0.1225" />
          <geometry>
            <mesh filename="package://we_r2_arm_description/meshes/_shoulder_link_2.stl" scale="1 1 1" />
          </geometry>
      </collision>
  </link>

  <link name="arm_1">
      <xacro:set_inertial_properties mass="5.4" ixx="0.02" iyy="0.02" izz="0.02" ixy="0.0" ixz="0.0" iyz="0.0" />
      <visual>
          <origin rpy="0 0 0"  xyz="-0.0975 0 -0.238" />
          <geometry>
            <mesh filename="package://we_r2_arm_description/meshes/_arm_link_1.stl" scale="1 1 1" />
          </geometry>
      </visual>
      <collision>
          <origin rpy="0 0 0"  xyz="-0.0975 0 -0.238" />
          <geometry>
            <mesh filename="package://we_r2_arm_description/meshes/_arm_link_1.stl" scale="1 1 1" />
          </geometry>
      </collision>
  </link>

  <link name="shoulder_3">
      <xacro:set_inertial_properties mass="5.4" ixx="0.02" iyy="0.02" izz="0.02" ixy="0.0" ixz="0.0" iyz="0.0" />
      <visual>
          <origin rpy="0 0 0"  xyz="-0.0975 0 -0.353" />
          <geometry>
            <mesh filename="package://we_r2_arm_description/meshes/_shoulder_link_3.stl" scale="1 1 1" />
          </geometry>
      </visual>
      <collision>
          <origin rpy="0 0 0"  xyz="-0.0975 0 -0.353" />
          <geometry>
            <mesh filename="package://we_r2_arm_description/meshes/_shoulder_link_3.stl" scale="1 1 1" />
          </geometry>
      </collision>
  </link>
  
  <link name="arm_2">
      <xacro:set_inertial_properties mass="5.4" ixx="0.02" iyy="0.02" izz="0.02" ixy="0.0" ixz="0.0" iyz="0.0" />
      <visual>
          <origin rpy="0 0 0"  xyz="-0.035 0 -0.353" />
          <geometry>
            <mesh filename="package://we_r2_arm_description/meshes/_arm_link_2.stl" scale="1 1 1" />
          </geometry>
      </visual>
      <collision>
          <origin rpy="0 0 0"  xyz="-0.035 0 -0.353" />
          <geometry>
            <mesh filename="package://we_r2_arm_description/meshes/_arm_link_2.stl" scale="1 1 1" />
          </geometry>
      </collision>
  </link>

  <link name="wrist_1">
      <xacro:set_inertial_properties mass="5.4" ixx="0.02" iyy="0.02" izz="0.02" ixy="0.0" ixz="0.0" iyz="0.0" />
      <visual>
          <origin rpy="0 0 0"  xyz="-0.035 0 -0.5655" />
          <geometry>
            <mesh filename="package://we_r2_arm_description/meshes/_wrist_link_1.stl" scale="1 1 1" />
          </geometry>
      </visual>
      <collision>
          <origin rpy="0 0 0"  xyz="-0.035 0 -0.5655" />
          <geometry>
            <mesh filename="package://we_r2_arm_description/meshes/_wrist_link_1.stl" scale="1 1 1" />
          </geometry>
      </collision>
  </link>

  <link name="wrist_2">
      <xacro:set_inertial_properties mass="5.4" ixx="0.02" iyy="0.02" izz="0.02" ixy="0.0" ixz="0.0" iyz="0.0" />
      <visual>
          <origin rpy="0 0 0"  xyz="-0.106 0 -0.5655" />
          <geometry>
            <mesh filename="package://we_r2_arm_description/meshes/_wrist_link_2.stl" scale="1 1 1" />
          </geometry>
      </visual>
      <collision>
          <origin rpy="0 0 0"  xyz="-0.106 0 -0.5655" />
          <geometry>
            <mesh filename="package://we_r2_arm_description/meshes/_wrist_link_2.stl" scale="1 1 1" />
          </geometry>
      </collision>
  </link>

  <link name="wrist_3">
      <xacro:set_inertial_properties mass="5.4" ixx="0.02" iyy="0.02" izz="0.02" ixy="0.0" ixz="0.0" iyz="0.0" />
      <visual>
          <origin rpy="0 0 0"  xyz="-0.106 0 -0.4955" />
          <geometry>
            <mesh filename="package://we_r2_arm_description/meshes/_wrist_link_3.stl" scale="1 1 1" />
          </geometry>
      </visual>
      <collision>
          <origin rpy="0 0 0"  xyz="-0.106 0 -0.4955" />
          <geometry>
            <mesh filename="package://we_r2_arm_description/meshes/_wrist_link_3.stl" scale="1 1 1" />
          </geometry>
      </collision>
  </link>

  <joint name="virtual_joint" type="fixed">
    <parent link="world" />
    <child link="base_link" />
    <origin rpy="0 0 0" xyz="0 0 0" />
  </joint>

  <joint name="joint_0" type="revolute">
    <parent link="base_link" />
    <child link="shoulder_1" />
    <origin rpy="0 0 0" xyz="0 0 0.09" />
    <axis xyz="0 0 1" />
    <limit lower="-${PI/2}" upper="${PI/2}" effort="${effort}" velocity="${velocity}" />
  </joint>

  <joint name="joint_1" type="revolute">
    <parent link="shoulder_1" />
    <child link="shoulder_2" />
    <origin rpy="0 0 0" xyz="0.0975 0 0.0375" />
    <axis xyz="1 0 0" />
    <limit lower="-${PI/2}" upper="${PI/2}" effort="${effort}" velocity="${velocity}" />
  </joint>

  <joint name="fix_s2_a1" type="fixed">
    <parent link="shoulder_2" />
    <child link="arm_1" />
    <origin rpy="0 0 0" xyz="0 0 0.115" />
  </joint>

  <joint name="fix_a1_s3" type="fixed">
    <parent link="arm_1" />
    <child link="shoulder_3" />
    <origin rpy="0 0 0" xyz="0 0 0.115" />
  </joint>

  <joint name="joint_2" type="revolute">
    <parent link="shoulder_3" />
    <child link="arm_2" />
    <origin rpy="0 0 0" xyz="-0.062 0 0" />
    <axis xyz="1 0 0" />
    <limit lower="-${PI/2}" upper="${PI/2}" effort="${effort}" velocity="${velocity}" />
  </joint>

  <joint name="joint_3" type="revolute">
    <parent link="arm_2" />
    <child link="wrist_1" />
    <origin rpy="0 0 0" xyz="0 0 0.2125" />
    <axis xyz="0 0 1" />
    <limit lower="-${PI/2}" upper="${PI/2}" effort="${effort}" velocity="${velocity}" />
  </joint>

  <joint name="joint_4" type="revolute">
    <parent link="wrist_1" />
    <child link="wrist_2" />
    <origin rpy="0 0 0" xyz="0.071 0 0" />
    <axis xyz="1 0 0" />
    <limit lower="-${PI/2}" upper="${PI/2}" effort="${effort}" velocity="${velocity}" />
  </joint>

  <joint name="joint_5" type="revolute">
    <parent link="wrist_2" />
    <child link="wrist_3" />
    <origin rpy="0 0 0" xyz="0 0 -0.07" />
    <axis xyz="0 0 1" />
    <limit lower="-${PI/2}" upper="${PI/2}" effort="${effort}" velocity="${velocity}" />
  </joint>

</robot>